{"uuid": "92bf26ad-1fb5-4061-8b39-8fa9f8828465", "children": ["c2afa529-6b23-4a66-bfb6-cad66e44dda9", "9760edf2-77d8-424e-8979-a068132c47a8", "f98beb0f-5a41-4564-86a3-a6aad5551044", "08589150-fa47-4534-86be-8ee2bf61ab9e", "196276de-8709-45c9-8764-e66961d3b929", "509813b9-6e3e-4033-8a69-d1756de01a1d", "15018d2e-384b-46c8-a01b-e3db65243528", "bd8e6ed4-7467-46cc-83f4-36f3738c8542", "94757e84-c871-46a2-a7a3-34c9c304d95f"], "befores": [{"name": "authorization", "status": "broken", "statusDetails": {"message": "requests.exceptions.ConnectionError: HTTPConnectionPool(host='127.0.0.1', port=8080): Max retries exceeded with url: /auth (Caused by NewConnectionError('<urllib3.connection.HTTPConnection object at 0x111caef90>: Failed to establish a new connection: [Errno 61] Connection refused'))\n", "trace": "  File \"/Library/Frameworks/Python.framework/Versions/3.11/lib/python3.11/site-packages/pluggy/_callers.py\", line 77, in _multicall\n    res = hook_impl.function(*args)\n          ^^^^^^^^^^^^^^^^^^^^^^^^^\n  File \"/Library/Frameworks/Python.framework/Versions/3.11/lib/python3.11/site-packages/_pytest/fixtures.py\", line 1123, in pytest_fixture_setup\n    result = call_fixture_func(fixturefunc, request, kwargs)\n             ^^^^^^^^^^^^^^^^^^^^^^^^^^^^^^^^^^^^^^^^^^^^^^^\n  File \"/Library/Frameworks/Python.framework/Versions/3.11/lib/python3.11/site-packages/_pytest/fixtures.py\", line 895, in call_fixture_func\n    fixture_result = next(generator)\n                     ^^^^^^^^^^^^^^^\n  File \"/Users/bogdankravcenko/PycharmProjects/aqa_hillel_kravchenko/lesson_24/conftest.py\", line 25, in authorization\n    response: Response = requests.post(f\"{BASE_URL}/auth\", auth=auth, verify=False)\n                         ^^^^^^^^^^^^^^^^^^^^^^^^^^^^^^^^^^^^^^^^^^^^^^^^^^^^^^^^^^\n  File \"/Library/Frameworks/Python.framework/Versions/3.11/lib/python3.11/site-packages/requests/api.py\", line 115, in post\n    return request(\"post\", url, data=data, json=json, **kwargs)\n           ^^^^^^^^^^^^^^^^^^^^^^^^^^^^^^^^^^^^^^^^^^^^^^^^^^^^\n  File \"/Library/Frameworks/Python.framework/Versions/3.11/lib/python3.11/site-packages/requests/api.py\", line 59, in request\n    return session.request(method=method, url=url, **kwargs)\n           ^^^^^^^^^^^^^^^^^^^^^^^^^^^^^^^^^^^^^^^^^^^^^^^^^\n  File \"/Library/Frameworks/Python.framework/Versions/3.11/lib/python3.11/site-packages/requests/sessions.py\", line 589, in request\n    resp = self.send(prep, **send_kwargs)\n           ^^^^^^^^^^^^^^^^^^^^^^^^^^^^^^\n  File \"/Library/Frameworks/Python.framework/Versions/3.11/lib/python3.11/site-packages/requests/sessions.py\", line 703, in send\n    r = adapter.send(request, **kwargs)\n        ^^^^^^^^^^^^^^^^^^^^^^^^^^^^^^^\n  File \"/Library/Frameworks/Python.framework/Versions/3.11/lib/python3.11/site-packages/requests/adapters.py\", line 519, in send\n    raise ConnectionError(e, request=request)\n"}, "start": 1730239569651, "stop": 1730239569663}], "start": 1730239569651, "stop": 1730239570546}