{"uuid": "68e455cd-cfc6-4cb6-828f-445fc9aab41b", "children": ["de4c54b6-707e-4908-bc69-cdb7f9c55826", "9c9e5bb6-0b2f-48a5-971b-2f1a4e50efce", "82af610c-8a85-4c10-832f-c74f7c724245", "d978e7e8-9841-4136-a360-a5032c15707b", "ff8f4b3c-b68e-4898-91c7-66f81477d247", "5cbcee11-ed16-4990-9566-73b3bde59826", "d7b0da1d-9cce-48f4-a95e-69fddc1466fc", "be8a1428-3643-4298-800b-388500aec296", "ebd4977a-93fa-4ab0-8213-a8324b239e32"], "befores": [{"name": "authorization", "status": "broken", "statusDetails": {"message": "requests.exceptions.ConnectionError: HTTPConnectionPool(host='127.0.0.1', port=8080): Max retries exceeded with url: /auth (Caused by NewConnectionError('<urllib3.connection.HTTPConnection object at 0x10f38f110>: Failed to establish a new connection: [Errno 61] Connection refused'))\n", "trace": "  File \"/Library/Frameworks/Python.framework/Versions/3.11/lib/python3.11/site-packages/pluggy/_callers.py\", line 77, in _multicall\n    res = hook_impl.function(*args)\n          ^^^^^^^^^^^^^^^^^^^^^^^^^\n  File \"/Library/Frameworks/Python.framework/Versions/3.11/lib/python3.11/site-packages/_pytest/fixtures.py\", line 1123, in pytest_fixture_setup\n    result = call_fixture_func(fixturefunc, request, kwargs)\n             ^^^^^^^^^^^^^^^^^^^^^^^^^^^^^^^^^^^^^^^^^^^^^^^\n  File \"/Library/Frameworks/Python.framework/Versions/3.11/lib/python3.11/site-packages/_pytest/fixtures.py\", line 895, in call_fixture_func\n    fixture_result = next(generator)\n                     ^^^^^^^^^^^^^^^\n  File \"/Users/bogdankravcenko/PycharmProjects/aqa_hillel_kravchenko/lesson_24/conftest.py\", line 25, in authorization\n    response: Response = requests.post(f\"{BASE_URL}/auth\", auth=auth, verify=False)\n                         ^^^^^^^^^^^^^^^^^^^^^^^^^^^^^^^^^^^^^^^^^^^^^^^^^^^^^^^^^^\n  File \"/Library/Frameworks/Python.framework/Versions/3.11/lib/python3.11/site-packages/requests/api.py\", line 115, in post\n    return request(\"post\", url, data=data, json=json, **kwargs)\n           ^^^^^^^^^^^^^^^^^^^^^^^^^^^^^^^^^^^^^^^^^^^^^^^^^^^^\n  File \"/Library/Frameworks/Python.framework/Versions/3.11/lib/python3.11/site-packages/requests/api.py\", line 59, in request\n    return session.request(method=method, url=url, **kwargs)\n           ^^^^^^^^^^^^^^^^^^^^^^^^^^^^^^^^^^^^^^^^^^^^^^^^^\n  File \"/Library/Frameworks/Python.framework/Versions/3.11/lib/python3.11/site-packages/requests/sessions.py\", line 589, in request\n    resp = self.send(prep, **send_kwargs)\n           ^^^^^^^^^^^^^^^^^^^^^^^^^^^^^^\n  File \"/Library/Frameworks/Python.framework/Versions/3.11/lib/python3.11/site-packages/requests/sessions.py\", line 703, in send\n    r = adapter.send(request, **kwargs)\n        ^^^^^^^^^^^^^^^^^^^^^^^^^^^^^^^\n  File \"/Library/Frameworks/Python.framework/Versions/3.11/lib/python3.11/site-packages/requests/adapters.py\", line 519, in send\n    raise ConnectionError(e, request=request)\n"}, "start": 1730239229642, "stop": 1730239229649}], "start": 1730239229642, "stop": 1730239230621}