{"uuid": "cc95199b-f79b-4d85-81d4-5acfe012ce35", "children": ["bbec41ad-1990-4d46-9bb9-b0d213b4aa44", "96617760-3736-460f-afe9-2e3a124cf1cf", "fdd64089-715b-47d0-a3dd-ed263fb610e8", "aede972f-024e-42fe-a293-de7f5759b684", "ccdf26f0-c85e-4912-8f98-4acd1b07d267", "c17b92e2-6b59-48bb-ad71-0fbc8fb820ad", "5ab6ba13-9b91-4c42-8a0c-d65afc1a4910", "ef7f5683-b0f0-47e7-ac69-10c2a49bc892", "4d0f34ec-cd33-4159-9fb1-48c8e012e8a3"], "befores": [{"name": "authorization", "status": "broken", "statusDetails": {"message": "requests.exceptions.ConnectionError: HTTPConnectionPool(host='127.0.0.1', port=8080): Max retries exceeded with url: /auth (Caused by NewConnectionError('<urllib3.connection.HTTPConnection object at 0x1096e2690>: Failed to establish a new connection: [Errno 61] Connection refused'))\n", "trace": "  File \"/Library/Frameworks/Python.framework/Versions/3.11/lib/python3.11/site-packages/pluggy/_callers.py\", line 77, in _multicall\n    res = hook_impl.function(*args)\n          ^^^^^^^^^^^^^^^^^^^^^^^^^\n  File \"/Library/Frameworks/Python.framework/Versions/3.11/lib/python3.11/site-packages/_pytest/fixtures.py\", line 1123, in pytest_fixture_setup\n    result = call_fixture_func(fixturefunc, request, kwargs)\n             ^^^^^^^^^^^^^^^^^^^^^^^^^^^^^^^^^^^^^^^^^^^^^^^\n  File \"/Library/Frameworks/Python.framework/Versions/3.11/lib/python3.11/site-packages/_pytest/fixtures.py\", line 895, in call_fixture_func\n    fixture_result = next(generator)\n                     ^^^^^^^^^^^^^^^\n  File \"/Users/bogdankravcenko/PycharmProjects/aqa_hillel_kravchenko/lesson_24/conftest.py\", line 25, in authorization\n    response: Response = requests.post(f\"{BASE_URL}/auth\", auth=auth, verify=False)\n                         ^^^^^^^^^^^^^^^^^^^^^^^^^^^^^^^^^^^^^^^^^^^^^^^^^^^^^^^^^^\n  File \"/Library/Frameworks/Python.framework/Versions/3.11/lib/python3.11/site-packages/requests/api.py\", line 115, in post\n    return request(\"post\", url, data=data, json=json, **kwargs)\n           ^^^^^^^^^^^^^^^^^^^^^^^^^^^^^^^^^^^^^^^^^^^^^^^^^^^^\n  File \"/Library/Frameworks/Python.framework/Versions/3.11/lib/python3.11/site-packages/requests/api.py\", line 59, in request\n    return session.request(method=method, url=url, **kwargs)\n           ^^^^^^^^^^^^^^^^^^^^^^^^^^^^^^^^^^^^^^^^^^^^^^^^^\n  File \"/Library/Frameworks/Python.framework/Versions/3.11/lib/python3.11/site-packages/requests/sessions.py\", line 589, in request\n    resp = self.send(prep, **send_kwargs)\n           ^^^^^^^^^^^^^^^^^^^^^^^^^^^^^^\n  File \"/Library/Frameworks/Python.framework/Versions/3.11/lib/python3.11/site-packages/requests/sessions.py\", line 703, in send\n    r = adapter.send(request, **kwargs)\n        ^^^^^^^^^^^^^^^^^^^^^^^^^^^^^^^\n  File \"/Library/Frameworks/Python.framework/Versions/3.11/lib/python3.11/site-packages/requests/adapters.py\", line 519, in send\n    raise ConnectionError(e, request=request)\n"}, "start": 1730239659280, "stop": 1730239659288}], "start": 1730239659279, "stop": 1730239660509}